<?xml version="1.0"?>
<robot xmlns:xacro="http://www.ros.org/wiki/xacro" >  
    <xacro:include filename="inertial_macros.xacro"/>
    <xacro:macro name="wheel" params="parent_prefix wheel_prefix reflect *joint_pose">
        <link name="${wheel_prefix}_wheel">
            <visual>
                <geometry>
                    <cylinder radius="${wheel_radius}" length="${wheel_thickness}"/>
                </geometry>
                <material name="blue"/>
            </visual>
            <collision>
                <geometry>
                    <sphere radius="${wheel_radius}"/>
                </geometry>
            </collision>
            <xacro:inertial_cylinder mass="${wheel_mass}" length="${wheel_thickness}" radius="${wheel_radius}">
                <origin xyz="0 0 0" rpy="0 0 0"/>
            </xacro:inertial_cylinder>
        </link>
        <joint name="${wheel_prefix}_wheel_joint" type="continuous">
            <parent link="${parent_prefix}"/>
            <child link="${wheel_prefix}_wheel"/>
            <xacro:insert_block name="joint_pose"/>
            <axis xyz="0 0 ${reflect*1}"/>
        </joint>
    </xacro:macro>
</robot>